Workbook
Name ㅁ1: #REF!

Sheet sheet1
A1: =RAND() -> 0.58474267 | B1: 4 | C1: LOL with 3000$ you could probably buy a real dog 😂
A2: =RAND() -> 0.80520854 | B2: 1 | C2: This was an underwhelming film to be honest. Very overrated.
A3: =RAND() -> 0.66411216 | B3: 0 | C3: i don’t like children.. but i’m obsessed with this child. Have him in every video please.
A4: =RAND() -> 0.23489461 | B4: 3 | C4: She's so pretty😍
A5: =RAND() -> 0.46817757 | B5: 4 | C5: Of this is out in 2018 imagine 2025 or 2030.
A6: =RAND() -> 0.78092134 | B6: 1 | C6: Munster. 100%
A7: =RAND() -> 0.81622388 | B7: 1 | C7: I must be losing my mind...this movie was HORRIBLE!!! by the end all I wanted it to do was be over so I could find a better use of my time. No!
A8: =RAND() -> 0.76057778 | B8: 2 | C8: can we get more likes than the rewind video???
A9: =RAND() -> 0.39968863 | B9: 4 | C9: Detroit: Become Pupper
A10: =RAND() -> 0.74548278 | B10: 0 | C10: It's 4 am. Go to sleep, Christopher
A11: =RAND() -> 0.2515164 | B11: 1 | C11: This movie would be perfect without all the plot holes
A12: =RAND() -> 0.09314233 | B12: 3 | C12: Your Beautiful ❤
... A38: =RAND() -> 0.53499316 | B38: 3 | C38: Her lips are gorgeous
A39: =RAND() -> 0.31101049 | B39: 4 | C39: 0.75833333
A40: =RAND() -> 0.61072525 | B40: 4 | C40: I just noticed that the rap part. Nobody ever talks about that guy
A41: =RAND() -> 0.30811092 | B41: 0 | C41: I really wanna know what the brand is of the eye drops she puts in in the beginning? 🥰
A42: =RAND() -> 0.74914927 | B42: 1 | C42: $3000 no way, $100 no way... wtf
A43: =RAND() -> 0.63319509 | B43: 4 | C43: Robo puppy mistreatment alert
A44: =RAND() -> 0.65697848 | B44: 2 | C44: There is no direct path from 2 to 5 so how can you change it from infinity to 18??
A45: =RAND() -> 0.10522826 | B45: 1 | C45: Damn Chris, I just saw it and I thought it sucked.
A46: =RAND() -> 0.41650492 | B46: 3 | C46: Everything about you is just WOW! Absolutely subbed! Not that my one sub would matter anything but still! 😅😍
A47: =RAND() -> 0.64413685 | B47: 4 | C47: I think what I'm most irritated about is people saying this movie is "true" cinema.
A48: =RAND() -> 0.25829761 | B48: 4 | C48: Wow, a model using drug store skin care products !! I stan
A49: =RAND() -> 0.71960309 | B49: 3 | C49: this was uploaded on my birthday 🥺 not that anyone cares but i finally found a video that was uploaded on my birthday 🤷🏽‍♀️
A50: =RAND() -> 0.20322924 | B50: 1 | C50: I saw it it wasnt that good.
A51: =RAND() -> 0.96356371 | B51: 1 | C51: Yep, I wasn’t one of those people sayin it looked ugly when we saw renders, and now that we have it in hand, everyone that said it was is in aw, and broke.
... A1333: =RAND() -> 0.63304351 | B1333: 4 | C1333: I edited this comment so no one will know what it was
A1334: =RAND() -> 0.97227578 | B1334: 4 | C1334: =- Tyra Banks -> #NAME?
A1335: =RAND() -> 0.91839981 | B1335: 2 | C1335: Where i can get this pencil eye liner?
A1336: =RAND() -> 0.68015093 | B1336: 4 | C1336: I felt that LEEEEANNNN to unlock a phone on a desk lollll
A1337: =RAND() -> 0.004535264 | B1337: 2 | C1337: Did anyone else see Loren legit lick her foundation..?
A1338: =RAND() -> 0.043900776 | B1338: 2 | C1338: Wht did you think on the differences in the story from the original?
A1339: =RAND() -> 0.62070633 | B1339: 3 | C1339: learned a lot from this video!thanks!it's just that whenever i put eyeliner,my lashes get's in the way and it get's realy messy
A1340: =RAND() -> 0.55746572 | B1340: 3 | C1340: Willow so pretty 😍
A1341: =RAND() -> 0.35069148 | B1341: 1 | C1341: Wait so you’re telling me you can see a pumpkin turn into a carriage and take a peasant girl to a ball only until 12 pm but not a princess who owns a trained tiger. Okie dokie.
A1342: =RAND() -> 0.52430253 | B1342: 4 | C1342: in the Past we bought phones with Camera. Now we're buying Cameras with phones
A1343: =RAND() -> 0.39461571 | B1343: 4 | C1343: Childhood dream but there wasn't robot's in that time
A1344: =RAND() -> 0.14824532 | B1344: 1 | C1344: I live for horror as well (as my blindingly obvious channel name lol) i have a library of books, and im a film fanatic too. Gonna watch this, sounds similar to Christopher Golden - Dead Ringers, but from your description the afore mentioned book seems darker
A1345: =RAND() -> 0.31032711 | B1345: 0 | C1345: Remember how in the movie it played f the police. F the police coming straight from the “underground” the underground is where the tethered come from. My cousin and I thought of this.
A1346: =RAND() -> 0.32216405 | B1346: 2 | C1346: Where is Oreo O's in the ranking???
...

Sheet copy
A2: 0 | B2: Bring back book review 2019!!! Like if agree
A3: 0 | B3: This is the PewDiePie I love the most. Please bring him out more often.
A4: 0 | B4: Please don't stop doing these videos. I love the music, the ambiance and of course the commentary. An awesome concept pewds keep it up!!
A5: 0 | B5: Please continue these book reviews, I absolutely love the insights and recommendations!
A6: 0 | B6: Dont stop the literature clib pooods, pleeeeeeze.
A7: 0 | B7: Don't stop making the book reviews Felix, they are so great and I look forward to hearing your thoughts about the books, as well as the authors. Much love
A8: 0 | B8: Okay guys, so ...i saved some money and i really struggle to find some good book - (i want everything though :D) but i only have money for one. So please, please please if you have any recommendation leave me a comment , i will appreciate it a lot . ♡♡
A9: 0 | B9: do more of these, its like reading the book by watching you review it
A10: 0 | B10: this series is AMAZING! please continue!
A11: 0 | B11: Please Review
A12: 0 | B12: 100% keep making these please! I will watch and like every single one.
A13: 0 | B13: I need more book review. Its been too long since i get 1 video of this content.
... A340: 4 | B340: Hello, my name is elder price, and I would like to share with you the most amazing book
A341: 4 | B341: 0.75833333
A342: 4 | B342: i would enjoy this book if i was younger 1:22
A343: 4 | B343: hears doki doki literature club music
A344: 4 | B344: You should read the myth of Sisyphus by Albert Camus
A345: 4 | B345: 2:51 was literally making a list for my d6, trying to decide what video game to play O.O
A346: 4 | B346: i have this book called “The Merciless II” and, even thought it’s not rated well (3.8/5), i still really enjoy it! i do like stories about possession and demons. the book can and WILL get a lil edgy from time to time, but besides that it’s pretty ok! very likable characters, great detail, and doesn’t shy away from RELLY gory and “edgy” stuff
A347: 4 | B347: AH! JUNJI ITO'S ADAPTION OF NO LONGER HUMAN 👌
A348: 4 | B348: No way.
A349: 4 | B349: 8:37 FINALLY I FOUND THE QUOTE AINSOAMSMSM
A350: 4 | B350: I love how pewds can’t figure out “overlook” and then turns around and uses “stoicism”
A351: 4 | B351: I think "Notes from Underground" from Dostoyevsky is the most interesting
A352: 4 | B352: Bungou Stray Dogs 🔥🔥
A353: 4 | B353: Meme review kills memes, while Book review brings books to life
... A510: 4 | B510: I have a video title in Russian
A511: 4 | B511: =- Ready player one -> #NAME?
A512: 4 | B512: For Crime and Punishment, the thematic part of the book was missed. Each character represents an ideology that was being discussed and debated in Russian society at the time, like utilitarianism, nihilism, etc. Dostoevsky does this often in his works. I personally found this aspect of the novel a MASTERPIECE! And yes, The Idiot is a really good one, but if you found the family aspect (which is usually central in most Russian classic literature), you'll find even more of it in The Idiot.
A513: 4 | B513: No longer human was anime adapted search it up and you’ll prolly find the anime and in the anime they did more serious literature adaptations. They change some stuff though like the wife of the MC had sex with the editor so he can get more time and she was not enjoying it she was crying and I think they were hinting it was rape I think idk because she said why didn’t you save me to him after but idrk she could’ve been talking about it in the bigger picture to how she “saved” him for loving her but all he’s done is caused her suffering for her loving him, idrk though. But tbh this “anime” really spoke to me I think a lot of us see ourselves in our MC and Dazai.
A514: 4 | B514: All the books reviewed:
A515: 4 | B515: clap clap
A516: 4 | B516: Crime and punishment and No Longer Human is really good 👍 I would recommend it to those who like dark moralistic stories
A517: 4 | B517: Theres ads! What a change. ヽ(ﾟ〇ﾟ)ﾉ
A518: 4 | B518: I have read "The Idiot" . A young man grow up in his formative years in a medical institution in Switzerland where he has never developed any artifice. He returns to Russian upper class society and the novel records his struggles to fit in -- as he doesn't know how to lie or gossip and as a result he does not have a charming personality.
A519: 4 | B519: that doki doki literature theme!!
A520: 4 | B520: I am here because of Bungou Stray Dogs 13:38
A521: 4 | B521: Never thought a guy screaming at a screen would turn out so intellectual
A522: 4 | B522: Pew's ASMR
A523: 4 | B523: Oh shittt you reviewed no longer human wo wow!!!
...

Sheet statistic
A1: 0 | B1: 1 | C1: 2 | D1: 3 | E1: 4 | G1: SUM
A2: =COUNTIF(sheet1!B2:'sheet1'!B7000,"0") -> 817 | B2: =COUNTIF(sheet1!B2:'sheet1'!B7000,"1") -> 1891 | C2: =COUNTIF(sheet1!B2:'sheet1'!B7000,"2") -> 1102 | D2: =COUNTIF(sheet1!B2:'sheet1'!B7000,"3") -> 1292 | E2: =COUNTIF(sheet1!B2:'sheet1'!B7000,"4") -> 1391 | G2: =SUM(A2:E2) -> 6493
A5: cereal | B5: https://www.youtube.com/watch?v=DHFGf-yq5Ng&t=12s | H5: 75 | I5: 95 | J5: 172 | K5: 185 | L5: 212
A6: iphone11 | B6: https://www.youtube.com/watch?v=DyX-QZZBgpw
A7: joker | B7: https://www.youtube.com/watch?v=1gzdlfCp2Iw
A8: github | B8: https://www.youtube.com/watch?v=Loav1kbA640
A9: wrongdijk | B9: https://www.youtube.com/watch?v=qx9sJ3O3JM0
A10: rewind | B10: https://www.youtube.com/watch?v=YbJOTdZBX1g&t=20s
B11: https://www.youtube.com/watch?v=wWsopDHAgVc | H11: 74 | I11: 9 | J11: 71 | K11: 262 | L11: 223
A12: book | B12: https://www.youtube.com/watch?v=sbPjVsfnS_c&t=19s | H12: 38 | I12: 298 | J12: 8 | K12: 380 | L12: 307
A13: dogbot | B13: https://www.youtube.com/watch?v=8t8fyiiQVZ0 | H13: 28 | I13: 75 | J13: 48 | K13: 397 | L13: 153
A14: winnie | B14: https://www.youtube.com/watch?v=gmxhy4aXOSQ | H14: 34 | I14: 5 | J14: 73 | K14: 57 | L14: 41
A15: codeproblem | B15: https://www.youtube.com/watch?v=GBuHSRDGZBY
A16: ramsay | B16: https://www.youtube.com/watch?v=ZJy1ajvMU1k
A17: marriage | B17: https://www.youtube.com/watch?v=M3NQE0BaAQw&feature=youtu.be
H18: 30 | I18: 30 | J18: 74 | K18: 298 | L18: 84
A19: eyeliner
A20: Friday
A21: rewind
A22: cereal
A23: daily
A24: wrongdijk
A25: git
A26: joker
A27: us
A28: spy
A29: cheeseburger
A30: aladin
